Workbook

Sheet APWeight3
A1: Character Stats (In Gear) | C1: Talents | E1: Weps/Sets/Relics | G1: Encounter/Target | I1: Buffs | K1: Consumables | M1: Final Attributes | O1: Final Encounter Parameters | T1: Threat coefficients (and other modifiers)
A2: Bonus Strength | B2: ='Main(manual)'!B2 -> 92 | C2: Ancestral Knowledge | D2: ='Main(manual)'!D2 -> 5 | E2: Min Weapon Dam | F2: ='Main(manual)'!F2 -> 259 | G2: Fight Duration (sec) | H2: ='Main(manual)'!H2 -> 60 | I2: Shield | J2: ='Main(manual)'!J2 -> Lightning | K2: # of Major Mana | L2: ='Main(manual)'!L2 -> 1 | M2: Strength | N2: =ROUNDDOWN((IF(B19="Tauren",90,86)+IF(B19="Orc",2,0)+$B$2+IF($L$5,25,0)+IF($L$13,20,0)+IF($L$10,25,0)+IF($J$11,16,0)+ROUNDDOWN(IF($J$12,77*(1+U6),0),0)+IF($L$8,30,0))*IF($J$10,1.1,1)*(($D$2*0.01)+1)*IF(F16,1+(0.05*$R$2),1)+IF(F19,((100*(1+(D2*0.01))*IF(J10,1.1,1))*P24*IF(F16,1+(0.05*$R$2),1)),0)+IF(F24,((50*(1+(D2*0.01))*IF(J10,1.1,1))*R3*IF(F16,1+(0.05*$R$2),1)),0),0) -> 370 | O2: Miss+Dodge% | P2: =10%+((H3-60)*1.5%)-(MIN(B8-300,15)*0.001)-MIN($N$6,((H3-60)*1%)+5%) -> 0.056 | Q2: T3.5 5pc Uptime | R2: =1 - EXP( -( (0.1 * (1 - SUM(P2:P3)) / C43) + IF(AND(J3="Windfury",C44>0),(0.1 * (1 - SUM(P2:P3)) / C44),0) ) * 12 ) -> 0.31589178 | T2: Totemic Alignment | U2: =D4*0.45 -> 0
A3: Melee AP | B3: ='Main(manual)'!B3+100 -> 100 | C3: Thundering Strikes | D3: ='Main(manual)'!D3 -> 5 | E3: Max Weapon Dam | F3: ='Main(manual)'!F3 -> 389 | G3: Level | H3: ='Main(manual)'!H3 -> 63 | I3: Imbue | J3: ='Main(manual)'!J3 -> Flametongue | K3: # of Tea | L3: ='Main(manual)'!L3 -> 1 | M3: Melee AP | N3: =ROUNDDOWN((100+$B$3+IF($J$15,55,0)+(($N$2*2)+IF($L$7,35,0)+IF($L$9,40,0)+(P20*130)+IF($J$8,290,0)+IF($J$9,222,0)+IF($J$15,30,0)+IF($J$3="Rockbiter",653,0)+IF(AND($J$3="Rockbiter",$F$11),653*U4,0)+IF($J$25,(120*(15/MAX(H2,15))))+IF($J$28,(260*(20/MAX(H2,20))))+IF($J$29,(200*(20/MAX(H2,20))))))*IF($J$15,1.05,1),0) -> 1562 | O3: Parry% | P3: =IF($H$3=63,14%,5%+(($H$3-60)*0.75%))*IF($H$5,0,1) -> 0 | Q3: ForgottenOrder | R3: =1-EXP(-((K67*(1-SUM(P2:P3))/C43)+IF(J3="Windfury",(K67*(1-SUM(P2:P3))/C44),0)+(K67*(1-SUM(P2:P3))/C46)+(K67*(1-SUM(P2:P3))/C49))*15) -> 0.42307324 | T3: Rockbiter | U3: 0.35
A4: Bonus Agility | B4: ='Main(manual)'!B4 -> 77 | C4: Totemic Alignment | D4: ='Main(manual)'!D4 -> 0 | E4: Weapon Speed | F4: ='Main(manual)'!F4 -> 3.6 | G4: No. of Targets | H4: ='Main(manual)'!H4 -> 1 | I4: Fire Totem | J4: ='Main(manual)'!J4 -> Nova+Searing | K4: # of Rune | L4: ='Main(manual)'!L4 -> 0 | M4: Agility | N4: =ROUNDDOWN(($B$4+IF(B19="Tauren",50,52)+IF(B19="Troll",5,0)+IF($J$11,16,0)+IF($L$6,25,0)+IF($L$11,25,0)+ROUNDDOWN(IF($J$13,77*(1+U6),0),0))*IF($J$10,1.1,1)*(($D$2*0.01)+1),0) -> 291 | O4: Block% | P4: =IF($H$5,0,5%) -> 0 | T4: T2.5 Rockbiter buff | U4: 0.25
A5: Phys Crit | B5: ='Main(manual)'!B5 -> 0.04 | C5: Calming Winds | D5: ='Main(manual)'!D5 -> 0 | E5: Stonebreaker Totem | F5: ='Main(manual)'!F5 -> TRUE | G5: Attacking Behind | H5: ='Main(manual)'!H5 -> TRUE | I5: Stoneclaw totem | J5: ='Main(manual)'!J5 -> FALSE | K5: Elixir of Giants | L5: ='Main(manual)'!L5 -> TRUE | M5: Phys Crit | N5: =$N$4/2000+($D$3/100)+IF($L$6,0.02,0)+IF(J14,0.03,0)+B5+0.017+(0.0004*($B$8-300)) -> 0.3077 | O5: Glancing Chance | P5: =10%+(10%*($H$3-60)) -> 0.4 | T5: Spirit Armor | U5: =0.05*D18*F20 -> 0
A6: Phys Hit | B6: ='Main(manual)'!B6 -> 0.02 | C6: Flurry | D6: ='Main(manual)'!D6 -> 5 | E6: Crackling Totem | F6: ='Main(manual)'!F6 -> TRUE | G6: Being Attacked | H6: ='Main(manual)'!H6 -> FALSE | I6: Salvation | J6: ='Main(manual)'!J6 -> TRUE | K6: Mongoose | L6: ='Main(manual)'!L6 -> TRUE | M6: Phys Hit | N6: =$B$6+($D$11/100)+(B8-300)*0.002 -> 0.076 | O6: Block Value | P6: 38 | T6: Enhancing Totems | U6: =0.125*D7 -> 0
A7: Haste | B7: ='Main(manual)'!B7 -> 0.03 | C7: Enhancing Totems | D7: ='Main(manual)'!D7 -> 0 | E7: Totem of Rage | F7: ='Main(manual)'!F7 -> TRUE | G7: Shield Proc Interval | H7: ='Main(manual)'!H7 -> 4 | I7: Tranquil Air | J7: ='Main(manual)'!J7 -> FALSE | K7: Firewater | L7: ='Main(manual)'!L7 -> TRUE | M7: Haste | N7: =(1+B7)*IF(F16,1+(0.1*R2),1)*IF($L$12,1.02,1)*IF($J$17,MIN(1+(0.2*(30/H2)),1.2),1)*(1+((IF(D6>=1,0.05,0)+($D$6*0.03))*P18))*(1+(0.08*$P$21))*IF($J$24,1+(0.1*(10/H2)),1)*IF($J$27,MIN(1+(0.2*(15/H2)),1.2),1)-1 -> 0.20648036 | O7: Glancing Damage | P7: =MIN(65%+((B8-300)*2%),95% ) -> 0.91 | T7: Calming Winds | U7: =0.0833*D5*NOT(F20) -> 0
A8: Weapon Skill | B8: ='Main(manual)'!B8 -> 313 | C8: Element's Grace | D8: ='Main(manual)'!D8 -> 4 | E8: Broken Earth totem | F8: ='Main(manual)'!F8 -> FALSE | G8: Armour | H8: ='Main(manual)'!H8 -> 4211 | I8: Battle Shout | J8: ='Main(manual)'!J8 -> TRUE | K8: Juju Power | L8: ='Main(manual)'!L8 -> FALSE | M8: Intellect | N8: =ROUNDDOWN(($B$10+IF(B19="Tauren",85,86)+IF(B19="Troll",1,0)+IF($J$18,31,0)+IF($J$11,16,0))*IF($J$10,1.1,1)*(1+($D$2*0.01)),0) -> 336 | O8: Hit% | P8: =100%-SUM(P2:P5)-MIN(P9,N5-((H3-60)*0.01)) -> 0.2663 | T8: Element's Grace | U8: =0.02*D8 -> 0.08
A9: Armor Pen | B9: ='Main(manual)'!B9 -> 500 | C9: Concussion | D9: ='Main(manual)'!D9 -> 5 | E9: Totem of Tides | F9: ='Main(manual)'!F9 -> FALSE | G9: Sunder Armour | H9: ='Main(manual)'!H9 -> TRUE | I9: Might | J9: ='Main(manual)'!J9 -> TRUE | K9: Juju Might | L9: ='Main(manual)'!L9 -> FALSE | M9: MP5 | N9: =$B$11+IF($L$15,12,0) -> 12 | O9: Crit Cap | P9: =100%-SUM(P2:P5) -> 0.544 | T9: Stormstrike | U9: =J23*0.25 -> 0.25
A10: Bonus Intellect | B10: ='Main(manual)'!B10 -> 157 | C10: Convection | D10: ='Main(manual)'!D10 -> 2 | E10: T2 3pc | F10: ='Main(manual)'!F11 -> FALSE | G10: Curse of Reck | H10: ='Main(manual)'!H10 -> TRUE | I10: Kings | J10: ='Main(manual)'!J10 -> TRUE | K10: R.O.I.D.S | L10: ='Main(manual)'!L10 -> TRUE | M10: Spirit | N10: =ROUNDDOWN(($B$12+IF($B$19="Tauren",102,101)+IF($B$19="Orc",1,0)+IF($L$14,50,0)+IF($J$19,40,0)+IF($J$11,16,0))*IF($J$10,1.1,1)*(1+($D$2*0.01)),0) -> 244 | O10: Crit% Post Suppression | P10: =N5-((H3-60)*0.01) -> 0.2777
A11: MP5 | B11: ='Main(manual)'!B11 -> 0 | C11: Ele Devastation | D11: ='Main(manual)'!D11 -> 3 | E11: T2.5 5pc | F11: ='Main(manual)'!F12 -> FALSE | G11: Faerie Fire | H11: ='Main(manual)'!H11 -> TRUE | I11: MotW | J11: ='Main(manual)'!J11 -> TRUE | K11: Scorpok Assay | L11: ='Main(manual)'!L11 -> FALSE | M11: Meditation | N11: =$B$13+IF($J$20,0.05,0) -> 0.05 | O11: Effective Armour | P11: =H8-B9-IF(H9,2250,0)-IF(H12,2550,0)+IF(AND(H9,H12),2250,0)-IF(H10,640,0)-IF(H11,505,0) -> 16
A12: Bonus Spirit | B12: ='Main(manual)'!B12 -> 5 | C12: Elemental Weapons | D12: ='Main(manual)'!D12 -> 3 | E12: T3 2pc | F12: ='Main(manual)'!F13 -> TRUE | G12: Improved EA | H12: ='Main(manual)'!H12 -> TRUE | I12: Strength of Earth | J12: ='Main(manual)'!J12 -> TRUE | K12: Tel'Abim Medley | L12: ='Main(manual)'!L12 -> FALSE | M12: Mana Per 2 (5SR) | N12: =(17+(($N$10/5)*$N$11)+($N$9/2.5))+IF($J$22,10,0)+IF($J$21,15.6,0) -> 49.84 | O12: Armour DR | P12: =P11 / (P11 + 400 + 85 * 60) -> 0.0029006526
A13: Meditation | B13: ='Main(manual)'!B13 -> 0 | C13: Reverberation | D13: ='Main(manual)'!D13 -> 3 | E13: T3 4pc | F13: ='Main(manual)'!F14 -> FALSE | G13: Hemorrhage | H13: ='Main(manual)'!H13 -> TRUE | I13: Grace of Air | J13: ='Main(manual)'!J13 -> TRUE | K13: Power Mushroom | L13: ='Main(manual)'!L13 -> FALSE | M13: Raw Mana Pool | N13: =1240+($N$8*15) -> 6280 | O13: NPC Level Resist | P13: =1-(($H$3-60)*0.02) -> 0.94
A14: Spell Pen | B14: ='Main(manual)'!B14 -> 0 | C14: Call of Flame | D14: ='Main(manual)'!D14 -> 3 | E14: T3 6pc | F14: ='Main(manual)'!F15 -> FALSE | G14: Gift of Arthas | H14: ='Main(manual)'!H14 -> FALSE | I14: Leader of Pack | J14: ='Main(manual)'!J14 -> TRUE | K14: Zanza | L14: ='Main(manual)'!L14 -> TRUE | M14: Final Mana Pool | N14: =N13+(L2*2250)+(L3*1350)+(L4*1550)+(H2/2*N12)+((N19*59/60)*H2)+IF(J2="Water",130*(H2/H7),0) -> 14160.987 | O14: Effective NR | P14: =(MAX($H$15-$B$14-IF($H$17,25,0),0)) -> 0
A15: Nature Spellpower | B15: ='Main(manual)'!B15 -> 385 | C15: Elemental Focus | D15: ='Main(manual)'!D15 -> 1 | E15: T3.5 3pc | F15: ='Main(manual)'!F16 -> FALSE | G15: NR | H15: ='Main(manual)'!H15 -> 15 | I15: Trueshot Aura | J15: ='Main(manual)'!J15 -> FALSE | K15: Mageblood | L15: ='Main(manual)'!L15 -> TRUE | M15: Nature Spellpower | N15: =B15+IF(L16,150,0)+IF(L17,35,0)+IF(L18,55,0)+IF(L20,35,0)+IF(L21,15,0)+IF(L22,22,0)+IF(F25,132*P22,0)+IF($J$25,(60*(15/MAX(H2,15)))) -> 739.76038 | O15: Effective FR | P15: =(MAX($H$16-$B$14-IF($H$18,75,0),0)) -> 0
A16: Fire Spellpower | B16: ='Main(manual)'!B16 -> 432 | C16: Improved Fire Totems | D16: ='Main(manual)'!D16 -> 2 | E16: T3.5 5pc | F16: ='Main(manual)'!F17 -> FALSE | G16: FR | H16: ='Main(manual)'!H16 -> 15 | I16: Boomy Aura | J16: ='Main(manual)'!J16 -> FALSE | K16: Supreme Power | L16: ='Main(manual)'!L16 -> TRUE | M16: Fire Spellpower | N16: =B16+IF(L16,150,0)+IF(L17,35,0)+IF(L19,40,0)+IF(L20,35,0)+IF(L21,15,0)+IF(L22,22,0)+IF(F25,132*P22,0)+IF($J$25,(60*(15/MAX(H2,15)))) -> 771.76038 | O16: Ele Dev Uptime | P16: =1 - EXP( -( (P10 * (1 - SUM(P2:P3)) / C43) + IF(J3="Windfury",(P10 * (1 - SUM(P2:P3)) / C44),0) + (MIN(1, P10 + 0.02 * D8) * (1 - SUM(P2:P3)) / C49) + (MIN(1, P10 + 0.02 * D8) * (1 - SUM(P2:P3)) / C46) ) * 10 ) -> 0.81284569
A17: Spell Crit | B17: ='Main(manual)'!B17 -> 0.07 | C17: Elemental Fury | D17: ='Main(manual)'!D17 -> 2 | E17: Threat Gloves | F17: ='Main(manual)'!F18 -> FALSE | G17: Thunderfury | H17: ='Main(manual)'!H17 -> TRUE | I17: Bloodlust | J17: ='Main(manual)'!J17 -> FALSE | K17: Arcane Elixir | L17: ='Main(manual)'!L17 -> TRUE | M17: Spell Crit | N17: =B17+(($N$8)/59.2)%+(IF(L21,2%,0))+3.53%+(IF(J16,3%,0)) -> 0.18205676 | O17: Focus Uptime | P17: =IF(D15,1-(((1-$P$10)^(5/C43))*(1-(1-SUM($P$2,$P$3))*$P$10)^2)*((1-MIN(IF($H$3=63,0.83+$N$18,0.96+$N$18-(($H$3-60)*0.01)),0.99)*($N$17+IF($F$10,0.1,0)+U8+IF($F$12,5%,0)))^2),0) -> 0.84695712
A18: Spell Hit | B18: ='Main(manual)'!B18 -> 0.03 | C18: Spirit Armor | D18: ='Main(manual)'!D18 -> 0 | E18: Subtlety Cloak | F18: ='Main(manual)'!F19 -> TRUE | G18: Curse of Elements | H18: ='Main(manual)'!H18 -> TRUE | I18: Arcane Intellect | J18: ='Main(manual)'!J18 -> TRUE | K18: Nature Power | L18: ='Main(manual)'!L18 -> TRUE | M18: Spell Hit | N18: =$P$16*MIN(B18+(D11*1%)+IF(J20,1%,0)+(D11*0.03),16%)+(1-$P$16)*MIN(B18+(D11*1%)+IF(J20,1%,0),16%) -> 0.14315611 | O18: Flurry Uptime | P18: =LET( miss, SUM($P$2,$P$3), wf_enabled, IF($J$3="Windfury", 1, 0), p_auto_base, $P$10 * (1 - miss), p_spell_base, MIN(1, $P$10 + 0.02 * $D$8) * (1 - miss), p_wf, $P$10 * (1 - miss), wf_chance, 0.2, wf_rolls, 2, p_auto_eff, p_auto_base + wf_enabled * wf_chance * (1 - (1 - p_wf)^wf_rolls) * (1 - p_auto_base), p_spell_eff, p_spell_base + wf_enabled * wf_chance * (1 - (1 - p_wf)^wf_rolls) * (1 - p_spell_base), r, p_auto_eff / MAX($C$43, 0.00001) + p_spell_eff / C49 + p_spell_eff / C46, a, 1 / MAX($C$43, 0.00001), rho, r / MAX(a, 0.00001), uptime_time, (rho * (3 + 3*rho + rho^2)) / (1 + rho)^3, uptime_time ) -> 0.70373105
A19: Race | B19: ='Main(manual)'!B19 -> Troll | C19: Imp Molten Blast | D19: ='Main(manual)'!D19 -> 1 | E19: Crusader | F19: ='Main(manual)'!F20 -> FALSE | G19: Improved Scorch | H19: ='Main(manual)'!H19 -> TRUE | I19: Divine Spirit | J19: ='Main(manual)'!J19 -> TRUE | K19: Fire Power | L19: ='Main(manual)'!L19 -> TRUE | M19: JoW Hits (60 sec) | N19: =IF($H$21,((60/C43)+14.166+IF(J3="Windfury",(60/C44),0)+IF(J3="Flametongue",((60/C43)+(60/C46)+(60/C49)),0)+$F$72)*0.5*(1-SUM($P$3,$P$2)),0) -> 47.216722 | O19: Windfury Procs (60 sec) | P19: =IF(J3="Windfury",((60/C43)+(60/C49)+(60/C46))*0.2*(1-SUM($P$3,$P$2)),0) -> 0
E20: Using Shield? | F20: ='Main(manual)'!F21 -> FALSE | G20: Nightfall | H20: ='Main(manual)'!H20 -> TRUE | I20: Emerald Blessing | J20: ='Main(manual)'!J20 -> TRUE | K20: Dreamtonic | L20: ='Main(manual)'!L20 -> TRUE | O20: Stonebreaker Uptime | P20: =IF($F$5,1-(0.65^(10/$C$51)),0) -> 0.5775
E21: Sulfuras proc | F21: ='Main(manual)'!F22 -> FALSE | G21: Judgement of Wisdom | H21: ='Main(manual)'!H21 -> TRUE | I21: Wisdom | J21: ='Main(manual)'!J21 -> TRUE | K21: Dreamshard | L21: ='Main(manual)'!L21 -> TRUE | O21: Crackling Uptime | P21: =IF($F$6,1-EXP(-(0.15/(60/(60/C46))*8)),0) -> 0.12482668
A22: TPS | B22: =$I$61 -> 1195.0257 | E22: Neretzek proc | F22: ='Main(manual)'!F23 -> FALSE | I22: Mana Spring | J22: ='Main(manual)'!J22 -> TRUE | K22: Tel'Abim Delight | L22: ='Main(manual)'!L22 -> FALSE | O22: WoC Uptime | P22: =1-EXP(-(0.05/(60/$H$72))*10) -> 0.49060891
A23: DPS | B23: =$G$61 -> 1797.6841 | E23: DTC proc | F23: ='Main(manual)'!F24 -> FALSE | I23: Stormstrike | J23: ='Main(manual)'!J23 -> TRUE | K23: D.Breath Chili | L23: ='Main(manual)'!L23 -> TRUE | O23: Nobility Drape Uptime | P23: =1-EXP(-(0.2/(60/$H$72))*6) -> 0.80188232
E24: Forgotten Order proc | F24: ='Main(manual)'!F25 -> FALSE | I24: Berserking | J24: ='Main(manual)'!J24 -> TRUE | O24: Crusader Uptime | P24: =1-EXP(-((E67*(1-SUM(P2:P3))/C43)+IF(J3="Windfury",(E67*(1-SUM(P2:P3))/C44),0)+(E67*(1-SUM(P2:P3))/C46)+(E67*(1-SUM(P2:P3))/C49))*20) -> 0.47644114
A25: Total | B25: %asPhys | C25: %asMagic | E25: Wrath of Cenarius | F25: ='Main(manual)'!F27 -> TRUE | I25: Bloodfury | J25: ='Main(manual)'!J25 -> FALSE | K25: Stat Weights | L25: Weight (dps) | M25: Weight (ap) | N25: Weight (sp)
A26: =Sum(K43:K59) -> 1 | B26: =K43+K46+K49+K44 -> 0.31389209 | C26: =1-B26 -> 0.68610791 | E26: # of spellstrike items | F26: ='Main(manual)'!F28 -> 1 | I26: Elemental Mastery | J26: ='Main(manual)'!J26 -> FALSE | K26: 1 AP = | L26: =(APWeight!B23-B23)/100 -> #REF! | M26: =L26/$L$26 -> #REF! | N26: =L26/$L$35 -> #REF!
E27: T1 5pc | F27: ='Main(manual)'!F10 -> FALSE | I27: Kiss of the Spider | J27: ='Main(manual)'!J27 -> FALSE | K27: 1 str = | L27: =(StrWeight!B23-B23)/100 -> #REF! | M27: =L27/$L$26 -> #REF! | N27: =L27/$L$35 -> #REF!
E28: Hand of Edward | F28: ='Main(manual)'!F26 -> None | I28: Slayer's Crest | J28: ='Main(manual)'!J28 -> FALSE | K28: 1 agi = | L28: =(AgiWeight!B23-B23)/100 -> #REF! | M28: =L28/$L$26 -> #REF! | N28: =L28/$L$35 -> #REF!
I29: Molten Emberstone | J29: ='Main(manual)'!J29 -> FALSE | K29: 1 int = | L29: =(IntWeight!B23-B23)/100 -> #REF! | M29: =L29/$L$26 -> #REF! | N29: =L29/$L$35 -> #REF!
K30: 1% phys crit = | L30: =PhysCritWeight!B23-B23 -> #REF! | M30: =L30/$L$26 -> #REF! | N30: =L30/$L$35 -> #REF!
K31: 1% phys hit = | L31: =PhysHitWeight!B23-B23 -> #REF! | M31: =L31/$L$26 -> #REF! | N31: =L31/$L$35 -> #REF!
K32: 1% haste = | L32: =HasteWeight!B23-B23 -> #REF! | M32: =L32/$L$26 -> #REF! | N32: =L32/$L$35 -> #REF!
K33: 1 wep skill = | L33: =(WepSkillWeight!B23-B23) -> #REF! | M33: =L33/$L$26 -> #REF! | N33: =L33/$L$35 -> #REF!
K34: 1 ArP = | L34: =ArPWeight!B23-B23 -> #REF! | M34: =L34/$L$26 -> #REF! | N34: =L34/$L$35 -> #REF!
K35: 1 SP = | L35: =L37+L36 -> #REF! | M35: =L35/$L$26 -> #REF! | N35: =L35/$L$35 -> #REF!
K36: 1 nature SP = | L36: =NatureWeight!B23-B23 -> #REF! | M36: =L36/$L$26 -> #REF! | N36: =L36/$L$35 -> #REF!
K37: 1 fire SP = | L37: =FireWeight!B23-B23 -> #REF! | M37: =L37/$L$26 -> #REF! | N37: =L37/$L$35 -> #REF!
K38: 1 spell crit = | L38: =SpellCritWeight!B23-B23 -> #REF! | M38: =L38/$L$26 -> #REF! | N38: =L38/$L$35 -> #REF!
K39: 1 spell hit = | L39: =(SpellHitWeight!B23-B23) -> #REF! | M39: =L39/$L$26 -> #REF! | N39: =L39/$L$35 -> #REF!
K40: 1 spell pen = | L40: =SpellPenWeight!B23-B23 -> #REF! | M40: =L40/$L$26 -> #REF! | N40: =L40/$L$35 -> #REF!
...

Sheet StrWeight3
A1: Character Stats (In Gear) | C1: Talents | E1: Weps/Sets/Relics | G1: Encounter/Target | I1: Buffs | K1: Consumables | M1: Final Attributes | O1: Final Encounter Parameters | T1: Threat coefficients (and other modifiers)
A2: Bonus Strength | B2: ='Main(manual)'!B2+100 -> 192 | C2: Ancestral Knowledge | D2: ='Main(manual)'!D2 -> 5 | E2: Min Weapon Dam | F2: ='Main(manual)'!F2 -> 259 | G2: Fight Duration (sec) | H2: ='Main(manual)'!H2 -> 60 | I2: Shield | J2: ='Main(manual)'!J2 -> Lightning | K2: # of Major Mana | L2: ='Main(manual)'!L2 -> 1 | M2: Strength | N2: =ROUNDDOWN((IF(B19="Tauren",90,86)+IF(B19="Orc",2,0)+$B$2+IF($L$5,25,0)+IF($L$13,20,0)+IF($L$10,25,0)+IF($J$11,16,0)+ROUNDDOWN(IF($J$12,77*(1+U6),0),0)+IF($L$8,30,0))*IF($J$10,1.1,1)*(($D$2*0.01)+1)*IF(F16,1+(0.05*$R$2),1)+IF(F19,((100*(1+(D2*0.01))*IF(J10,1.1,1))*P24*IF(F16,1+(0.05*$R$2),1)),0)+IF(F24,((50*(1+(D2*0.01))*IF(J10,1.1,1))*R3*IF(F16,1+(0.05*$R$2),1)),0),0) -> 486 | O2: Miss+Dodge% | P2: =10%+((H3-60)*1.5%)-(MIN(B8-300,15)*0.001)-MIN($N$6,((H3-60)*1%)+5%) -> 0.056 | Q2: T3.5 5pc Uptime | R2: =1 - EXP( -( (0.1 * (1 - SUM(P2:P3)) / C43) + IF(AND(J3="Windfury",C44>0),(0.1 * (1 - SUM(P2:P3)) / C44),0) ) * 12 ) -> 0.31589178 | T2: Totemic Alignment | U2: =D4*0.45 -> 0
A3: Melee AP | B3: ='Main(manual)'!B3 -> 0 | C3: Thundering Strikes | D3: ='Main(manual)'!D3 -> 5 | E3: Max Weapon Dam | F3: ='Main(manual)'!F3 -> 389 | G3: Level | H3: ='Main(manual)'!H3 -> 63 | I3: Imbue | J3: ='Main(manual)'!J3 -> Flametongue | K3: # of Tea | L3: ='Main(manual)'!L3 -> 1 | M3: Melee AP | N3: =ROUNDDOWN((100+$B$3+IF($J$15,55,0)+(($N$2*2)+IF($L$7,35,0)+IF($L$9,40,0)+(P20*130)+IF($J$8,290,0)+IF($J$9,222,0)+IF($J$15,30,0)+IF($J$3="Rockbiter",653,0)+IF(AND($J$3="Rockbiter",$F$11),653*U4,0)+IF($J$25,(120*(15/MAX(H2,15))))+IF($J$28,(260*(20/MAX(H2,20))))+IF($J$29,(200*(20/MAX(H2,20))))))*IF($J$15,1.05,1),0) -> 1694 | O3: Parry% | P3: =IF($H$3=63,14%,5%+(($H$3-60)*0.75%))*IF($H$5,0,1) -> 0 | Q3: ForgottenOrder | R3: =1-EXP(-((K67*(1-SUM(P2:P3))/C43)+IF(J3="Windfury",(K67*(1-SUM(P2:P3))/C44),0)+(K67*(1-SUM(P2:P3))/C46)+(K67*(1-SUM(P2:P3))/C49))*15) -> 0.42307324 | T3: Rockbiter | U3: 0.35
A4: Bonus Agility | B4: ='Main(manual)'!B4 -> 77 | C4: Totemic Alignment | D4: ='Main(manual)'!D4 -> 0 | E4: Weapon Speed | F4: ='Main(manual)'!F4 -> 3.6 | G4: No. of Targets | H4: ='Main(manual)'!H4 -> 1 | I4: Fire Totem | J4: ='Main(manual)'!J4 -> Nova+Searing | K4: # of Rune | L4: ='Main(manual)'!L4 -> 0 | M4: Agility | N4: =ROUNDDOWN(($B$4+IF(B19="Tauren",50,52)+IF(B19="Troll",5,0)+IF($J$11,16,0)+IF($L$6,25,0)+IF($L$11,25,0)+ROUNDDOWN(IF($J$13,77*(1+U6),0),0))*IF($J$10,1.1,1)*(($D$2*0.01)+1),0) -> 291 | O4: Block% | P4: =IF($H$5,0,5%) -> 0 | T4: T2.5 Rockbiter buff | U4: 0.25
A5: Phys Crit | B5: ='Main(manual)'!B5 -> 0.04 | C5: Calming Winds | D5: ='Main(manual)'!D5 -> 0 | E5: Stonebreaker Totem | F5: ='Main(manual)'!F5 -> TRUE | G5: Attacking Behind | H5: ='Main(manual)'!H5 -> TRUE | I5: Stoneclaw totem | J5: ='Main(manual)'!J5 -> FALSE | K5: Elixir of Giants | L5: ='Main(manual)'!L5 -> TRUE | M5: Phys Crit | N5: =$N$4/2000+($D$3/100)+IF($L$6,0.02,0)+IF(J14,0.03,0)+B5+0.017+(0.0004*($B$8-300)) -> 0.3077 | O5: Glancing Chance | P5: =10%+(10%*($H$3-60)) -> 0.4 | T5: Spirit Armor | U5: =0.05*D18*F20 -> 0
A6: Phys Hit | B6: ='Main(manual)'!B6 -> 0.02 | C6: Flurry | D6: ='Main(manual)'!D6 -> 5 | E6: Crackling Totem | F6: ='Main(manual)'!F6 -> TRUE | G6: Being Attacked | H6: ='Main(manual)'!H6 -> FALSE | I6: Salvation | J6: ='Main(manual)'!J6 -> TRUE | K6: Mongoose | L6: ='Main(manual)'!L6 -> TRUE | M6: Phys Hit | N6: =$B$6+($D$11/100)+(B8-300)*0.002 -> 0.076 | O6: Block Value | P6: 38 | T6: Enhancing Totems | U6: =0.125*D7 -> 0
A7: Haste | B7: ='Main(manual)'!B7 -> 0.03 | C7: Enhancing Totems | D7: ='Main(manual)'!D7 -> 0 | E7: Totem of Rage | F7: ='Main(manual)'!F7 -> TRUE | G7: Shield Proc Interval | H7: ='Main(manual)'!H7 -> 4 | I7: Tranquil Air | J7: ='Main(manual)'!J7 -> FALSE | K7: Firewater | L7: ='Main(manual)'!L7 -> TRUE | M7: Haste | N7: =(1+B7)*IF(F16,1+(0.1*R2),1)*IF($L$12,1.02,1)*IF($J$17,MIN(1+(0.2*(30/H2)),1.2),1)*(1+((IF(D6>=1,0.05,0)+($D$6*0.03))*P18))*(1+(0.08*$P$21))*IF($J$24,1+(0.1*(10/H2)),1)*IF($J$27,MIN(1+(0.2*(15/H2)),1.2),1)-1 -> 0.20648036 | O7: Glancing Damage | P7: =MIN(65%+((B8-300)*2%),95% ) -> 0.91 | T7: Calming Winds | U7: =0.0833*D5*NOT(F20) -> 0
A8: Weapon Skill | B8: ='Main(manual)'!B8 -> 313 | C8: Element's Grace | D8: ='Main(manual)'!D8 -> 4 | E8: Broken Earth totem | F8: ='Main(manual)'!F8 -> FALSE | G8: Armour | H8: ='Main(manual)'!H8 -> 4211 | I8: Battle Shout | J8: ='Main(manual)'!J8 -> TRUE | K8: Juju Power | L8: ='Main(manual)'!L8 -> FALSE | M8: Intellect | N8: =ROUNDDOWN(($B$10+IF(B19="Tauren",85,86)+IF(B19="Troll",1,0)+IF($J$18,31,0)+IF($J$11,16,0))*IF($J$10,1.1,1)*(1+($D$2*0.01)),0) -> 336 | O8: Hit% | P8: =100%-SUM(P2:P5)-MIN(P9,N5-((H3-60)*0.01)) -> 0.2663 | T8: Element's Grace | U8: =0.02*D8 -> 0.08
A9: Armor Pen | B9: ='Main(manual)'!B9 -> 500 | C9: Concussion | D9: ='Main(manual)'!D9 -> 5 | E9: Totem of Tides | F9: ='Main(manual)'!F9 -> FALSE | G9: Sunder Armour | H9: ='Main(manual)'!H9 -> TRUE | I9: Might | J9: ='Main(manual)'!J9 -> TRUE | K9: Juju Might | L9: ='Main(manual)'!L9 -> FALSE | M9: MP5 | N9: =$B$11+IF($L$15,12,0) -> 12 | O9: Crit Cap | P9: =100%-SUM(P2:P5) -> 0.544 | T9: Stormstrike | U9: =J23*0.25 -> 0.25
A10: Bonus Intellect | B10: ='Main(manual)'!B10 -> 157 | C10: Convection | D10: ='Main(manual)'!D10 -> 2 | E10: T2 3pc | F10: ='Main(manual)'!F11 -> FALSE | G10: Curse of Reck | H10: ='Main(manual)'!H10 -> TRUE | I10: Kings | J10: ='Main(manual)'!J10 -> TRUE | K10: R.O.I.D.S | L10: ='Main(manual)'!L10 -> TRUE | M10: Spirit | N10: =ROUNDDOWN(($B$12+IF($B$19="Tauren",102,101)+IF($B$19="Orc",1,0)+IF($L$14,50,0)+IF($J$19,40,0)+IF($J$11,16,0))*IF($J$10,1.1,1)*(1+($D$2*0.01)),0) -> 244 | O10: Crit% Post Suppression | P10: =N5-((H3-60)*0.01) -> 0.2777
A11: MP5 | B11: ='Main(manual)'!B11 -> 0 | C11: Ele Devastation | D11: ='Main(manual)'!D11 -> 3 | E11: T2.5 5pc | F11: ='Main(manual)'!F12 -> FALSE | G11: Faerie Fire | H11: ='Main(manual)'!H11 -> TRUE | I11: MotW | J11: ='Main(manual)'!J11 -> TRUE | K11: Scorpok Assay | L11: ='Main(manual)'!L11 -> FALSE | M11: Meditation | N11: =$B$13+IF($J$20,0.05,0) -> 0.05 | O11: Effective Armour | P11: =H8-B9-IF(H9,2250,0)-IF(H12,2550,0)+IF(AND(H9,H12),2250,0)-IF(H10,640,0)-IF(H11,505,0) -> 16
A12: Bonus Spirit | B12: ='Main(manual)'!B12 -> 5 | C12: Elemental Weapons | D12: ='Main(manual)'!D12 -> 3 | E12: T3 2pc | F12: ='Main(manual)'!F13 -> TRUE | G12: Improved EA | H12: ='Main(manual)'!H12 -> TRUE | I12: Strength of Earth | J12: ='Main(manual)'!J12 -> TRUE | K12: Tel'Abim Medley | L12: ='Main(manual)'!L12 -> FALSE | M12: Mana Per 2 (5SR) | N12: =(17+(($N$10/5)*$N$11)+($N$9/2.5))+IF($J$22,10,0)+IF($J$21,15.6,0) -> 49.84 | O12: Armour DR | P12: =P11 / (P11 + 400 + 85 * 60) -> 0.0029006526
A13: Meditation | B13: ='Main(manual)'!B13 -> 0 | C13: Reverberation | D13: ='Main(manual)'!D13 -> 3 | E13: T3 4pc | F13: ='Main(manual)'!F14 -> FALSE | G13: Hemorrhage | H13: ='Main(manual)'!H13 -> TRUE | I13: Grace of Air | J13: ='Main(manual)'!J13 -> TRUE | K13: Power Mushroom | L13: ='Main(manual)'!L13 -> FALSE | M13: Raw Mana Pool | N13: =1240+($N$8*15) -> 6280 | O13: NPC Level Resist | P13: =1-(($H$3-60)*0.02) -> 0.94
A14: Spell Pen | B14: ='Main(manual)'!B14 -> 0 | C14: Call of Flame | D14: ='Main(manual)'!D14 -> 3 | E14: T3 6pc | F14: ='Main(manual)'!F15 -> FALSE | G14: Gift of Arthas | H14: ='Main(manual)'!H14 -> FALSE | I14: Leader of Pack | J14: ='Main(manual)'!J14 -> TRUE | K14: Zanza | L14: ='Main(manual)'!L14 -> TRUE | M14: Final Mana Pool | N14: =N13+(L2*2250)+(L3*1350)+(L4*1550)+(H2/2*N12)+((N19*59/60)*H2)+IF(J2="Water",130*(H2/H7),0) -> 14160.987 | O14: Effective NR | P14: =(MAX($H$15-$B$14-IF($H$17,25,0),0)) -> 0
A15: Nature Spellpower | B15: ='Main(manual)'!B15 -> 385 | C15: Elemental Focus | D15: ='Main(manual)'!D15 -> 1 | E15: T3.5 3pc | F15: ='Main(manual)'!F16 -> FALSE | G15: NR | H15: ='Main(manual)'!H15 -> 15 | I15: Trueshot Aura | J15: ='Main(manual)'!J15 -> FALSE | K15: Mageblood | L15: ='Main(manual)'!L15 -> TRUE | M15: Nature Spellpower | N15: =B15+IF(L16,150,0)+IF(L17,35,0)+IF(L18,55,0)+IF(L20,35,0)+IF(L21,15,0)+IF(L22,22,0)+IF(F25,132*P22,0)+IF($J$25,(60*(15/MAX(H2,15)))) -> 739.76038 | O15: Effective FR | P15: =(MAX($H$16-$B$14-IF($H$18,75,0),0)) -> 0
A16: Fire Spellpower | B16: ='Main(manual)'!B16 -> 432 | C16: Improved Fire Totems | D16: ='Main(manual)'!D16 -> 2 | E16: T3.5 5pc | F16: ='Main(manual)'!F17 -> FALSE | G16: FR | H16: ='Main(manual)'!H16 -> 15 | I16: Boomy Aura | J16: ='Main(manual)'!J16 -> FALSE | K16: Supreme Power | L16: ='Main(manual)'!L16 -> TRUE | M16: Fire Spellpower | N16: =B16+IF(L16,150,0)+IF(L17,35,0)+IF(L19,40,0)+IF(L20,35,0)+IF(L21,15,0)+IF(L22,22,0)+IF(F25,132*P22,0)+IF($J$25,(60*(15/MAX(H2,15)))) -> 771.76038 | O16: Ele Dev Uptime | P16: =1 - EXP( -( (P10 * (1 - SUM(P2:P3)) / C43) + IF(J3="Windfury",(P10 * (1 - SUM(P2:P3)) / C44),0) + (MIN(1, P10 + 0.02 * D8) * (1 - SUM(P2:P3)) / C49) + (MIN(1, P10 + 0.02 * D8) * (1 - SUM(P2:P3)) / C46) ) * 10 ) -> 0.81284569
A17: Spell Crit | B17: ='Main(manual)'!B17 -> 0.07 | C17: Elemental Fury | D17: ='Main(manual)'!D17 -> 2 | E17: Threat Gloves | F17: ='Main(manual)'!F18 -> FALSE | G17: Thunderfury | H17: ='Main(manual)'!H17 -> TRUE | I17: Bloodlust | J17: ='Main(manual)'!J17 -> FALSE | K17: Arcane Elixir | L17: ='Main(manual)'!L17 -> TRUE | M17: Spell Crit | N17: =B17+(($N$8)/59.2)%+(IF(L21,2%,0))+3.53%+(IF(J16,3%,0)) -> 0.18205676 | O17: Focus Uptime | P17: =IF(D15,1-(((1-$P$10)^(5/C43))*(1-(1-SUM($P$2,$P$3))*$P$10)^2)*((1-MIN(IF($H$3=63,0.83+$N$18,0.96+$N$18-(($H$3-60)*0.01)),0.99)*($N$17+IF($F$10,0.1,0)+U8+IF($F$12,5%,0)))^2),0) -> 0.84695712
A18: Spell Hit | B18: ='Main(manual)'!B18 -> 0.03 | C18: Spirit Armor | D18: ='Main(manual)'!D18 -> 0 | E18: Subtlety Cloak | F18: ='Main(manual)'!F19 -> TRUE | G18: Curse of Elements | H18: ='Main(manual)'!H18 -> TRUE | I18: Arcane Intellect | J18: ='Main(manual)'!J18 -> TRUE | K18: Nature Power | L18: ='Main(manual)'!L18 -> TRUE | M18: Spell Hit | N18: =$P$16*MIN(B18+(D11*1%)+IF(J20,1%,0)+(D11*0.03),16%)+(1-$P$16)*MIN(B18+(D11*1%)+IF(J20,1%,0),16%) -> 0.14315611 | O18: Flurry Uptime | P18: =LET( miss, SUM($P$2,$P$3), wf_enabled, IF($J$3="Windfury", 1, 0), p_auto_base, $P$10 * (1 - miss), p_spell_base, MIN(1, $P$10 + 0.02 * $D$8) * (1 - miss), p_wf, $P$10 * (1 - miss), wf_chance, 0.2, wf_rolls, 2, p_auto_eff, p_auto_base + wf_enabled * wf_chance * (1 - (1 - p_wf)^wf_rolls) * (1 - p_auto_base), p_spell_eff, p_spell_base + wf_enabled * wf_chance * (1 - (1 - p_wf)^wf_rolls) * (1 - p_spell_base), r, p_auto_eff / MAX($C$43, 0.00001) + p_spell_eff / C49 + p_spell_eff / C46, a, 1 / MAX($C$43, 0.00001), rho, r / MAX(a, 0.00001), uptime_time, (rho * (3 + 3*rho + rho^2)) / (1 + rho)^3, uptime_time ) -> 0.70373105
A19: Race | B19: ='Main(manual)'!B19 -> Troll | C19: Imp Molten Blast | D19: ='Main(manual)'!D19 -> 1 | E19: Crusader | F19: ='Main(manual)'!F20 -> FALSE | G19: Improved Scorch | H19: ='Main(manual)'!H19 -> TRUE | I19: Divine Spirit | J19: ='Main(manual)'!J19 -> TRUE | K19: Fire Power | L19: ='Main(manual)'!L19 -> TRUE | M19: JoW Hits (60 sec) | N19: =IF($H$21,((60/C43)+14.166+IF(J3="Windfury",(60/C44),0)+IF(J3="Flametongue",((60/C43)+(60/C46)+(60/C49)),0)+$F$72)*0.5*(1-SUM($P$3,$P$2)),0) -> 47.216722 | O19: Windfury Procs (60 sec) | P19: =IF(J3="Windfury",((60/C43)+(60/C49)+(60/C46))*0.2*(1-SUM($P$3,$P$2)),0) -> 0
E20: Using Shield? | F20: ='Main(manual)'!F21 -> FALSE | G20: Nightfall | H20: ='Main(manual)'!H20 -> TRUE | I20: Emerald Blessing | J20: ='Main(manual)'!J20 -> TRUE | K20: Dreamtonic | L20: ='Main(manual)'!L20 -> TRUE | O20: Stonebreaker Uptime | P20: =IF($F$5,1-(0.65^(10/$C$51)),0) -> 0.5775
E21: Sulfuras proc | F21: ='Main(manual)'!F22 -> FALSE | G21: Judgement of Wisdom | H21: ='Main(manual)'!H21 -> TRUE | I21: Wisdom | J21: ='Main(manual)'!J21 -> TRUE | K21: Dreamshard | L21: ='Main(manual)'!L21 -> TRUE | O21: Crackling Uptime | P21: =IF($F$6,1-EXP(-(0.15/(60/(60/C46))*8)),0) -> 0.12482668
A22: TPS | B22: =$I$61 -> 1225.6396 | E22: Neretzek proc | F22: ='Main(manual)'!F23 -> FALSE | I22: Mana Spring | J22: ='Main(manual)'!J22 -> TRUE | K22: Tel'Abim Delight | L22: ='Main(manual)'!L22 -> FALSE | O22: WoC Uptime | P22: =1-EXP(-(0.05/(60/$H$72))*10) -> 0.49060891
A23: DPS | B23: =$G$61 -> 1837.7668 | E23: DTC proc | F23: ='Main(manual)'!F24 -> FALSE | I23: Stormstrike | J23: ='Main(manual)'!J23 -> TRUE | K23: D.Breath Chili | L23: ='Main(manual)'!L23 -> TRUE | O23: Nobility Drape Uptime | P23: =1-EXP(-(0.2/(60/$H$72))*6) -> 0.80188232
E24: Forgotten Order proc | F24: ='Main(manual)'!F25 -> FALSE | I24: Berserking | J24: ='Main(manual)'!J24 -> TRUE | O24: Crusader Uptime | P24: =1-EXP(-((E67*(1-SUM(P2:P3))/C43)+IF(J3="Windfury",(E67*(1-SUM(P2:P3))/C44),0)+(E67*(1-SUM(P2:P3))/C46)+(E67*(1-SUM(P2:P3))/C49))*20) -> 0.47644114
A25: Total | B25: %asPhys | C25: %asMagic | E25: Wrath of Cenarius | F25: ='Main(manual)'!F27 -> TRUE | I25: Bloodfury | J25: ='Main(manual)'!J25 -> FALSE | K25: Stat Weights | L25: Weight (dps) | M25: Weight (ap) | N25: Weight (sp)
A26: =Sum(K43:K59) -> 1 | B26: =K43+K46+K49+K44 -> 0.32140811 | C26: =1-B26 -> 0.67859189 | E26: # of spellstrike items | F26: ='Main(manual)'!F28 -> 1 | I26: Elemental Mastery | J26: ='Main(manual)'!J26 -> FALSE | K26: 1 AP = | L26: =(APWeight!B23-B23)/100 -> #REF! | M26: =L26/$L$26 -> #REF! | N26: =L26/$L$35 -> #REF!
E27: T1 5pc | F27: ='Main(manual)'!F10 -> FALSE | I27: Kiss of the Spider | J27: ='Main(manual)'!J27 -> FALSE | K27: 1 str = | L27: =(StrWeight!B23-B23)/100 -> #REF! | M27: =L27/$L$26 -> #REF! | N27: =L27/$L$35 -> #REF!
E28: Hand of Edward | F28: ='Main(manual)'!F26 -> None | I28: Slayer's Crest | J28: ='Main(manual)'!J28 -> FALSE | K28: 1 agi = | L28: =(AgiWeight!B23-B23)/100 -> #REF! | M28: =L28/$L$26 -> #REF! | N28: =L28/$L$35 -> #REF!
I29: Molten Emberstone | J29: ='Main(manual)'!J29 -> FALSE | K29: 1 int = | L29: =(IntWeight!B23-B23)/100 -> #REF! | M29: =L29/$L$26 -> #REF! | N29: =L29/$L$35 -> #REF!
K30: 1% phys crit = | L30: =PhysCritWeight!B23-B23 -> #REF! | M30: =L30/$L$26 -> #REF! | N30: =L30/$L$35 -> #REF!
K31: 1% phys hit = | L31: =PhysHitWeight!B23-B23 -> #REF! | M31: =L31/$L$26 -> #REF! | N31: =L31/$L$35 -> #REF!
K32: 1% haste = | L32: =HasteWeight!B23-B23 -> #REF! | M32: =L32/$L$26 -> #REF! | N32: =L32/$L$35 -> #REF!
K33: 1 wep skill = | L33: =(WepSkillWeight!B23-B23) -> #REF! | M33: =L33/$L$26 -> #REF! | N33: =L33/$L$35 -> #REF!
K34: 1 ArP = | L34: =ArPWeight!B23-B23 -> #REF! | M34: =L34/$L$26 -> #REF! | N34: =L34/$L$35 -> #REF!
K35: 1 SP = | L35: =L37+L36 -> #REF! | M35: =L35/$L$26 -> #REF! | N35: =L35/$L$35 -> #REF!
K36: 1 nature SP = | L36: =NatureWeight!B23-B23 -> #REF! | M36: =L36/$L$26 -> #REF! | N36: =L36/$L$35 -> #REF!
K37: 1 fire SP = | L37: =FireWeight!B23-B23 -> #REF! | M37: =L37/$L$26 -> #REF! | N37: =L37/$L$35 -> #REF!
K38: 1 spell crit = | L38: =SpellCritWeight!B23-B23 -> #REF! | M38: =L38/$L$26 -> #REF! | N38: =L38/$L$35 -> #REF!
K39: 1 spell hit = | L39: =(SpellHitWeight!B23-B23) -> #REF! | M39: =L39/$L$26 -> #REF! | N39: =L39/$L$35 -> #REF!
K40: 1 spell pen = | L40: =SpellPenWeight!B23-B23 -> #REF! | M40: =L40/$L$26 -> #REF! | N40: =L40/$L$35 -> #REF!
...

Sheet StrWeight4
A1: Character Stats (In Gear) | C1: Talents | E1: Weps/Sets/Relics | G1: Encounter/Target | I1: Buffs | K1: Consumables | M1: Final Attributes | O1: Final Encounter Parameters | T1: Threat coefficients (and other modifiers)
A2: Bonus Strength | B2: ='Main(automatic)'!B2+100 -> 336 | C2: Ancestral Knowledge | D2: ='Main(automatic)'!D2 -> 5 | E2: Min Weapon Dam | F2: ='Main(automatic)'!F2 -> 242 | G2: Fight Duration (sec) | H2: ='Main(automatic)'!H2 -> 90 | I2: Shield | J2: ='Main(automatic)'!J2 -> Lightning | K2: # of Major Mana | L2: ='Main(automatic)'!L2 -> 2 | M2: Strength | N2: =ROUNDDOWN((IF(B19="Tauren",90,86)+IF(B19="Orc",2,0)+$B$2+IF($L$5,25,0)+IF($L$13,20,0)+IF($L$10,25,0)+IF($J$11,16,0)+ROUNDDOWN(IF($J$12,77*(1+U6),0),0)+IF($L$8,30,0))*IF($J$10,1.1,1)*(($D$2*0.01)+1)*IF(F16,1+(0.05*$R$2),1)+IF(F19,((100*(1+(D2*0.01))*IF(J10,1.1,1))*P24*IF(F16,1+(0.05*$R$2),1)),0)+IF(F24,((50*(1+(D2*0.01))*IF(J10,1.1,1))*R3*IF(F16,1+(0.05*$R$2),1)),0),0) -> 721 | O2: Miss+Dodge% | P2: =10%+((H3-60)*1.5%)-(MIN(B8-300,15)*0.001)-MIN($N$6,((H3-60)*1%)+5%) -> 0.053 | Q2: T3.5 5pc Uptime | R2: =1 - EXP( -( (0.1 * (1 - SUM(P2:P3)) / C43) + IF(AND(J3="Windfury",C44>0),(0.1 * (1 - SUM(P2:P3)) / C44),0) ) * 12 ) -> 0.49878497 | T2: Totemic Alignment | U2: =D4*0.45 -> 0
A3: Melee AP | B3: ='Main(automatic)'!B3 -> 198 | C3: Thundering Strikes | D3: ='Main(automatic)'!D3 -> 5 | E3: Max Weapon Dam | F3: ='Main(automatic)'!F3 -> 366 | G3: Level | H3: ='Main(automatic)'!H3 -> 63 | I3: Imbue | J3: ='Main(automatic)'!J3 -> Windfury | K3: # of Tea | L3: ='Main(automatic)'!L3 -> 2 | M3: Melee AP | N3: =ROUNDDOWN((100+$B$3+IF($J$15,55,0)+(($N$2*2)+IF($L$7,35,0)+IF($L$9,40,0)+(P20*130)+IF($J$8,290,0)+IF($J$9,222,0)+IF($J$15,30,0)+IF($J$3="Rockbiter",653,0)+IF(AND($J$3="Rockbiter",$F$11),653*U4,0)+IF($J$25,(120*(15/MAX(H2,15))))+IF($J$28,(260*(20/MAX(H2,20))))+IF($J$29,(200*(20/MAX(H2,20))))))*IF($J$15,1.05,1),0) -> 2307 | O3: Parry% | P3: =IF($H$3=63,14%,5%+(($H$3-60)*0.75%))*IF($H$5,0,1) -> 0 | Q3: ForgottenOrder | R3: =1-EXP(-((K67*(1-SUM(P2:P3))/C43)+IF(J3="Windfury",(K67*(1-SUM(P2:P3))/C44),0)+(K67*(1-SUM(P2:P3))/C46)+(K67*(1-SUM(P2:P3))/C49))*15) -> 0.55744088 | T3: Rockbiter | U3: 0.35
A4: Bonus Agility | B4: ='Main(automatic)'!B4 -> 195 | C4: Totemic Alignment | D4: ='Main(automatic)'!D4 -> 0 | E4: Weapon Speed | F4: ='Main(automatic)'!F4 -> 3.6 | G4: No. of Targets | H4: ='Main(automatic)'!H4 -> 1 | I4: Fire Totem | J4: ='Main(automatic)'!J4 -> None | K4: # of Rune | L4: ='Main(automatic)'!L4 -> 0 | M4: Agility | N4: =ROUNDDOWN(($B$4+IF(B19="Tauren",50,52)+IF(B19="Troll",5,0)+IF($J$11,16,0)+IF($L$6,25,0)+IF($L$11,25,0)+ROUNDDOWN(IF($J$13,77*(1+U6),0),0))*IF($J$10,1.1,1)*(($D$2*0.01)+1),0) -> 470 | O4: Block% | P4: =IF($H$5,0,5%) -> 0 | T4: T2.5 Rockbiter buff | U4: 0.25
A5: Phys Crit | B5: ='Main(automatic)'!B5 -> 0.16 | C5: Calming Winds | D5: ='Main(automatic)'!D5 -> 3 | E5: Stonebreaker Totem | F5: ='Main(automatic)'!F5 -> FALSE | G5: Attacking Behind | H5: ='Main(automatic)'!H5 -> TRUE | I5: Stoneclaw totem | J5: ='Main(automatic)'!J5 -> FALSE | K5: Elixir of Giants | L5: ='Main(automatic)'!L5 -> TRUE | M5: Phys Crit | N5: =$N$4/2000+($D$3/100)+IF($L$6,0.02,0)+IF(J14,0.03,0)+B5+0.017+(0.0004*($B$8-300)) -> 0.5168 | O5: Glancing Chance | P5: =10%+(10%*($H$3-60)) -> 0.4 | T5: Spirit Armor | U5: =0.05*D18*F20 -> 0
A6: Phys Hit | B6: ='Main(automatic)'!B6 -> 0.04 | C6: Flurry | D6: ='Main(automatic)'!D6 -> 5 | E6: Crackling Totem | F6: ='Main(automatic)'!F6 -> FALSE | G6: Being Attacked | H6: ='Main(automatic)'!H6 -> TRUE | I6: Salvation | J6: ='Main(automatic)'!J6 -> TRUE | K6: Mongoose | L6: ='Main(automatic)'!L6 -> TRUE | M6: Phys Hit | N6: =$B$6+($D$11/100)+(B8-300)*0.002 -> 0.094 | O6: Block Value | P6: 38 | T6: Enhancing Totems | U6: =0.125*D7 -> 0.25
A7: Haste | B7: ='Main(automatic)'!B7 -> 0.082644412 | C7: Enhancing Totems | D7: ='Main(automatic)'!D7 -> 2 | E7: Totem of Rage | F7: ='Main(automatic)'!F7 -> FALSE | G7: Shield Proc Interval | H7: ='Main(automatic)'!H7 -> 4 | I7: Tranquil Air | J7: ='Main(automatic)'!J7 -> FALSE | K7: Firewater | L7: ='Main(automatic)'!L7 -> TRUE | M7: Haste | N7: =(1+B7)*IF(F16,1+(0.1*R2),1)*IF($L$12,1.02,1)*IF($J$17,MIN(1+(0.2*(30/H2)),1.2),1)*(1+((IF(D6>=1,0.05,0)+($D$6*0.03))*P18))*(1+(0.08*$P$21))*IF($J$24,1+(0.1*(10/H2)),1)*IF($J$27,MIN(1+(0.2*(15/H2)),1.2),1)-1 -> 0.35346035 | O7: Glancing Damage | P7: =MIN(65%+((B8-300)*2%),95% ) -> 0.89 | T7: Calming Winds | U7: =0.0833*D5*NOT(F20) -> 0.2499
A8: Weapon Skill | B8: ='Main(automatic)'!B8 -> 312 | C8: Element's Grace | D8: ='Main(automatic)'!D8 -> 5 | E8: Broken Earth totem | F8: ='Main(automatic)'!F8 -> FALSE | G8: Armour | H8: ='Main(automatic)'!H8 -> 4211 | I8: Battle Shout | J8: ='Main(automatic)'!J8 -> TRUE | K8: Juju Power | L8: ='Main(automatic)'!L8 -> FALSE | M8: Intellect | N8: =ROUNDDOWN(($B$10+IF(B19="Tauren",85,86)+IF(B19="Troll",1,0)+IF($J$18,31,0)+IF($J$11,16,0))*IF($J$10,1.1,1)*(1+($D$2*0.01)),0) -> 274 | O8: Hit% | P8: =100%-SUM(P2:P5)-MIN(P9,N5-((H3-60)*0.01)) -> 0.0602 | T8: Element's Grace | U8: =0.02*D8 -> 0.1
A9: Armor Pen | B9: ='Main(automatic)'!B9 -> 400 | C9: Concussion | D9: ='Main(automatic)'!D9 -> 5 | E9: Totem of Tides | F9: ='Main(automatic)'!F9 -> FALSE | G9: Sunder Armour | H9: ='Main(automatic)'!H9 -> TRUE | I9: Might | J9: ='Main(automatic)'!J9 -> TRUE | K9: Juju Might | L9: ='Main(automatic)'!L9 -> FALSE | M9: MP5 | N9: =$B$11+IF($L$15,12,0) -> 0 | O9: Crit Cap | P9: =100%-SUM(P2:P5) -> 0.547 | T9: Stormstrike | U9: =J23*0.25 -> 0.25
A10: Bonus Intellect | B10: ='Main(automatic)'!B10 -> 106 | C10: Convection | D10: ='Main(automatic)'!D10 -> 0 | E10: T2 3pc | F10: ='Main(automatic)'!F11 -> FALSE | G10: Curse of Reck | H10: ='Main(automatic)'!H10 -> TRUE | I10: Kings | J10: ='Main(automatic)'!J10 -> TRUE | K10: R.O.I.D.S | L10: ='Main(automatic)'!L10 -> FALSE | M10: Spirit | N10: =ROUNDDOWN(($B$12+IF($B$19="Tauren",102,101)+IF($B$19="Orc",1,0)+IF($L$14,50,0)+IF($J$19,40,0)+IF($J$11,16,0))*IF($J$10,1.1,1)*(1+($D$2*0.01)),0) -> 244 | O10: Crit% Post Suppression | P10: =N5-((H3-60)*0.01) -> 0.4868
A11: MP5 | B11: ='Main(automatic)'!B11 -> 0 | C11: Ele Devastation | D11: ='Main(automatic)'!D11 -> 3 | E11: T2.5 5pc | F11: ='Main(automatic)'!F12 -> FALSE | G11: Faerie Fire | H11: ='Main(automatic)'!H11 -> TRUE | I11: MotW | J11: ='Main(automatic)'!J11 -> TRUE | K11: Scorpok Assay | L11: ='Main(automatic)'!L11 -> TRUE | M11: Meditation | N11: =$B$13+IF($J$20,0.05,0) -> 0.05 | O11: Effective Armour | P11: =H8-B9-IF(H9,2250,0)-IF(H12,2550,0)+IF(AND(H9,H12),2250,0)-IF(H10,640,0)-IF(H11,505,0) -> 116
A12: Bonus Spirit | B12: ='Main(automatic)'!B12 -> 4 | C12: Elemental Weapons | D12: ='Main(automatic)'!D12 -> 3 | E12: T3 2pc | F12: ='Main(automatic)'!F13 -> TRUE | G12: Improved EA | H12: ='Main(automatic)'!H12 -> TRUE | I12: Strength of Earth | J12: ='Main(automatic)'!J12 -> TRUE | K12: Tel'Abim Medley | L12: ='Main(automatic)'!L12 -> FALSE | M12: Mana Per 2 (5SR) | N12: =(17+(($N$10/5)*$N$11)+($N$9/2.5))+IF($J$22,10,0)+IF($J$21,15.6,0) -> 45.04 | O12: Armour DR | P12: =P11 / (P11 + 400 + 85 * 60) -> 0.020655271
A13: Meditation | B13: ='Main(automatic)'!B13 -> 0 | C13: Reverberation | D13: ='Main(automatic)'!D13 -> 3 | E13: T3 4pc | F13: ='Main(automatic)'!F14 -> TRUE | G13: Hemorrhage | H13: ='Main(automatic)'!H13 -> FALSE | I13: Grace of Air | J13: ='Main(automatic)'!J13 -> TRUE | K13: Power Mushroom | L13: ='Main(automatic)'!L13 -> FALSE | M13: Raw Mana Pool | N13: =1240+($N$8*15) -> 5350 | O13: NPC Level Resist | P13: =1-(($H$3-60)*0.02) -> 0.94
A14: Spell Pen | B14: ='Main(automatic)'!B14 -> 0 | C14: Call of Flame | D14: ='Main(automatic)'!D14 -> 2 | E14: T3 6pc | F14: ='Main(automatic)'!F15 -> TRUE | G14: Gift of Arthas | H14: ='Main(automatic)'!H14 -> FALSE | I14: Leader of Pack | J14: ='Main(automatic)'!J14 -> TRUE | K14: Zanza | L14: ='Main(automatic)'!L14 -> TRUE | M14: Final Mana Pool | N14: =N13+(L2*2250)+(L3*1350)+(L4*1550)+(H2/2*N12)+((N19*59/60)*H2)+IF(J2="Water",130*(H2/H7),0) -> 16698.641 | O14: Effective NR | P14: =(MAX($H$15-$B$14-IF($H$17,25,0),0)) -> 0
A15: Nature Spellpower | B15: ='Main(automatic)'!B15 -> 0 | C15: Elemental Focus | D15: ='Main(automatic)'!D15 -> 1 | E15: T3.5 3pc | F15: ='Main(automatic)'!F16 -> FALSE | G15: NR | H15: ='Main(automatic)'!H15 -> 15 | I15: Trueshot Aura | J15: ='Main(automatic)'!J15 -> FALSE | K15: Mageblood | L15: ='Main(automatic)'!L15 -> FALSE | M15: Nature Spellpower | N15: =B15+IF(L16,150,0)+IF(L17,35,0)+IF(L18,55,0)+IF(L20,35,0)+IF(L21,15,0)+IF(L22,22,0)+IF(F25,132*P22,0)+IF($J$25,(60*(15/MAX(H2,15)))) -> 65 | O15: Effective FR | P15: =(MAX($H$16-$B$14-IF($H$18,75,0),0)) -> 110
A16: Fire Spellpower | B16: ='Main(automatic)'!B16 -> 0 | C16: Improved Fire Totems | D16: ='Main(automatic)'!D16 -> 0 | E16: T3.5 5pc | F16: ='Main(automatic)'!F17 -> FALSE | G16: FR | H16: ='Main(automatic)'!H16 -> 185 | I16: Boomy Aura | J16: ='Main(automatic)'!J16 -> FALSE | K16: Supreme Power | L16: ='Main(automatic)'!L16 -> FALSE | M16: Fire Spellpower | N16: =B16+IF(L16,150,0)+IF(L17,35,0)+IF(L19,40,0)+IF(L20,35,0)+IF(L21,15,0)+IF(L22,22,0)+IF(F25,132*P22,0)+IF($J$25,(60*(15/MAX(H2,15)))) -> 10 | O16: Ele Dev Uptime | P16: =1 - EXP( -( (P10 * (1 - SUM(P2:P3)) / C43) + IF(J3="Windfury",(P10 * (1 - SUM(P2:P3)) / C44),0) + (MIN(1, P10 + 0.02 * D8) * (1 - SUM(P2:P3)) / C49) + (MIN(1, P10 + 0.02 * D8) * (1 - SUM(P2:P3)) / C46) ) * 10 ) -> 0.98365919
A17: Spell Crit | B17: ='Main(automatic)'!B17 -> 0 | C17: Elemental Fury | D17: ='Main(automatic)'!D17 -> 0 | E17: Threat Gloves | F17: ='Main(automatic)'!F18 -> FALSE | G17: Thunderfury | H17: ='Main(automatic)'!H17 -> TRUE | I17: Bloodlust | J17: ='Main(automatic)'!J17 -> TRUE | K17: Arcane Elixir | L17: ='Main(automatic)'!L17 -> FALSE | M17: Spell Crit | N17: =B17+(($N$8)/59.2)%+(IF(L21,2%,0))+3.53%+(IF(J16,3%,0)) -> 0.081583784 | O17: Focus Uptime | P17: =IF(D15,1-(((1-$P$10)^(5/C43))*(1-(1-SUM($P$2,$P$3))*$P$10)^2)*((1-MIN(IF($H$3=63,0.83+$N$18,0.96+$N$18-(($H$3-60)*0.01)),0.99)*($N$17+IF($F$10,0.1,0)+U8+IF($F$12,5%,0)))^2),0) -> 0.94981719
A18: Spell Hit | B18: ='Main(automatic)'!B18 -> 0 | C18: Spirit Armor | D18: ='Main(automatic)'!D18 -> 0 | E18: Subtlety Cloak | F18: ='Main(automatic)'!F19 -> FALSE | G18: Curse of Elements | H18: ='Main(automatic)'!H18 -> TRUE | I18: Arcane Intellect | J18: ='Main(automatic)'!J18 -> TRUE | K18: Nature Power | L18: ='Main(automatic)'!L18 -> TRUE | M18: Spell Hit | N18: =$P$16*MIN(B18+(D11*1%)+IF(J20,1%,0)+(D11*0.03),16%)+(1-$P$16)*MIN(B18+(D11*1%)+IF(J20,1%,0),16%) -> 0.12852933 | O18: Flurry Uptime | P18: =LET( miss, SUM($P$2,$P$3), wf_enabled, IF($J$3="Windfury", 1, 0), p_auto_base, $P$10 * (1 - miss), p_spell_base, MIN(1, $P$10 + 0.02 * $D$8) * (1 - miss), p_wf, $P$10 * (1 - miss), wf_chance, 0.2, wf_rolls, 2, p_auto_eff, p_auto_base + wf_enabled * wf_chance * (1 - (1 - p_wf)^wf_rolls) * (1 - p_auto_base), p_spell_eff, p_spell_base + wf_enabled * wf_chance * (1 - (1 - p_wf)^wf_rolls) * (1 - p_spell_base), r, p_auto_eff / MAX($C$43, 0.00001) + p_spell_eff / C49 + p_spell_eff / C46, a, 1 / MAX($C$43, 0.00001), rho, r / MAX(a, 0.00001), uptime_time, (rho * (3 + 3*rho + rho^2)) / (1 + rho)^3, uptime_time ) -> 0.86004538
A19: Race | B19: ='Main(automatic)'!B19 -> Tauren | E19: Crusader | F19: ='Main(automatic)'!F20 -> TRUE | G19: Improved Scorch | H19: ='Main(automatic)'!H19 -> TRUE | I19: Divine Spirit | J19: ='Main(automatic)'!J19 -> TRUE | K19: Fire Power | L19: ='Main(automatic)'!L19 -> FALSE | M19: JoW Hits (60 sec) | N19: =IF($H$21,((60/C43)+14.166+IF(J3="Windfury",(60/C44),0)+IF(J3="Flametongue",((60/C43)+(60/C46)+(60/C49)),0)+$F$72)*0.5*(1-SUM($P$3,$P$2)),0) -> 23.975603 | O19: Windfury Procs (60 sec) | P19: =IF(J3="Windfury",((60/C43)+(60/C49)+(60/C46))*0.2*(1-SUM($P$3,$P$2)),0) -> 6.9555898
A20: Weapon Skill Book | B20: ='Main(automatic)'!B20 -> TRUE | E20: Using Shield? | F20: ='Main(automatic)'!F21 -> FALSE | G20: Nightfall | H20: ='Main(automatic)'!H20 -> FALSE | I20: Emerald Blessing | J20: ='Main(automatic)'!J20 -> TRUE | K20: Dreamtonic | L20: ='Main(automatic)'!L20 -> FALSE | O20: Stonebreaker Uptime | P20: =IF($F$5,1-(0.65^(10/$C$51)),0) -> 0
A21: Orc Racial Weapon Skill | B21: ='Main(automatic)'!B21 -> FALSE | E21: Sulfuras proc | F21: ='Main(automatic)'!F22 -> FALSE | G21: Judgement of Wisdom | H21: ='Main(automatic)'!H21 -> TRUE | I21: Wisdom | J21: ='Main(automatic)'!J21 -> TRUE | K21: Dreamshard | L21: ='Main(automatic)'!L21 -> FALSE | O21: Crackling Uptime | P21: =IF($F$6,1-(0.85^(8/$C$46)),0) -> 0
A22: TPS | B22: =$I$61 -> 1042.0601 | E22: Neretzek proc | F22: ='Main(automatic)'!F23 -> FALSE | I22: Mana Spring | J22: ='Main(automatic)'!J22 -> TRUE | K22: Tel'Abim Delight | L22: ='Main(automatic)'!L22 -> FALSE | O22: WoC Uptime | P22: =1-EXP(-(0.05/(60/$H$72))*10) -> 0.35594089
A23: DPS | B23: =$G$61 -> 1614.5217 | E23: DTC proc | F23: ='Main(automatic)'!F24 -> FALSE | I23: Stormstrike | J23: ='Main(automatic)'!J23 -> TRUE | O23: Nobility Drape Uptime | P23: =1-EXP(-(0.2/(60/$H$72))*6) -> 0.65212618
E24: Forgotten Order proc | F24: ='Main(automatic)'!F25 -> FALSE | I24: Berserking | J24: ='Main(automatic)'!J24 -> FALSE | O24: Crusader Uptime | P24: =1-EXP(-((E67*(1-SUM(P2:P3))/C43)+IF(J3="Windfury",(E67*(1-SUM(P2:P3))/C44),0)+(E67*(1-SUM(P2:P3))/C46)+(E67*(1-SUM(P2:P3))/C49))*20) -> 0.61673811
A25: Total | B25: %asPhys | C25: %asMagic | E25: Wrath of Cenarius | F25: ='Main(automatic)'!F26 -> FALSE | I25: Bloodfury | J25: ='Main(automatic)'!J25 -> TRUE | K25: Stat Weights | L25: Weight (dps) | M25: Weight (ap) | N25: Weight (sp)
A26: =Sum(K43:K59) -> 1 | B26: =K43+K46+K49+K44 -> 0.71843651 | C26: =1-B26 -> 0.28156349 | E26: # of spellstrike items | F26: ='Main(automatic)'!F27 -> 0 | I26: Elemental Mastery | J26: ='Main(automatic)'!J26 -> FALSE | K26: 1 AP = | L26: =(APWeight!B23-B23)/100 -> #REF! | M26: =L26/$L$26 -> #REF! | N26: =L26/$L$35 -> #REF!
E27: T1 5pc | F27: ='Main(automatic)'!F10 -> FALSE | I27: Kiss of the Spider | J27: ='Main(automatic)'!J27 -> FALSE | K27: 1 str = | L27: =(StrWeight!B23-B23)/100 -> #REF! | M27: =L27/$L$26 -> #REF! | N27: =L27/$L$35 -> #REF!
I28: Slayer's Crest | J28: ='Main(automatic)'!J28 -> FALSE | K28: 1 agi = | L28: =(AgiWeight!B23-B23)/100 -> #REF! | M28: =L28/$L$26 -> #REF! | N28: =L28/$L$35 -> #REF!
I29: Molten Emberstone | J29: ='Main(automatic)'!J29 -> FALSE | K29: 1 int = | L29: =(IntWeight!B23-B23)/100 -> #REF! | M29: =L29/$L$26 -> #REF! | N29: =L29/$L$35 -> #REF!
K30: 1% phys crit = | L30: =PhysCritWeight!B23-B23 -> #REF! | M30: =L30/$L$26 -> #REF! | N30: =L30/$L$35 -> #REF!
K31: 1% phys hit = | L31: =PhysHitWeight!B23-B23 -> #REF! | M31: =L31/$L$26 -> #REF! | N31: =L31/$L$35 -> #REF!
K32: 1% haste = | L32: =HasteWeight!B23-B23 -> #REF! | M32: =L32/$L$26 -> #REF! | N32: =L32/$L$35 -> #REF!
K33: 1 wep skill = | L33: =(WepSkillWeight!B23-B23) -> #REF! | M33: =L33/$L$26 -> #REF! | N33: =L33/$L$35 -> #REF!
K34: 1 ArP = | L34: =ArPWeight!B23-B23 -> #REF! | M34: =L34/$L$26 -> #REF! | N34: =L34/$L$35 -> #REF!
K35: 1 SP = | L35: =L37+L36 -> #REF! | M35: =L35/$L$26 -> #REF! | N35: =L35/$L$35 -> #REF!
K36: 1 nature SP = | L36: =NatureWeight!B23-B23 -> #REF! | M36: =L36/$L$26 -> #REF! | N36: =L36/$L$35 -> #REF!
K37: 1 fire SP = | L37: =FireWeight!B23-B23 -> #REF! | M37: =L37/$L$26 -> #REF! | N37: =L37/$L$35 -> #REF!
K38: 1 spell crit = | L38: =SpellCritWeight!B23-B23 -> #REF! | M38: =L38/$L$26 -> #REF! | N38: =L38/$L$35 -> #REF!
K39: 1 spell hit = | L39: =(SpellHitWeight!B23-B23) -> #REF! | M39: =L39/$L$26 -> #REF! | N39: =L39/$L$35 -> #REF!
K40: 1 spell pen = | L40: =SpellPenWeight!B23-B23 -> #REF! | M40: =L40/$L$26 -> #REF! | N40: =L40/$L$35 -> #REF!
...

Sheet AgiWeight3
A1: Character Stats (In Gear) | C1: Talents | E1: Weps/Sets/Relics | G1: Encounter/Target | I1: Buffs | K1: Consumables | M1: Final Attributes | O1: Final Encounter Parameters | T1: Threat coefficients (and other modifiers)
A2: Bonus Strength | B2: ='Main(manual)'!B2 -> 92 | C2: Ancestral Knowledge | D2: ='Main(manual)'!D2 -> 5 | E2: Min Weapon Dam | F2: ='Main(manual)'!F2 -> 259 | G2: Fight Duration (sec) | H2: ='Main(manual)'!H2 -> 60 | I2: Shield | J2: ='Main(manual)'!J2 -> Lightning | K2: # of Major Mana | L2: ='Main(manual)'!L2 -> 1 | M2: Strength | N2: =ROUNDDOWN((IF(B19="Tauren",90,86)+IF(B19="Orc",2,0)+$B$2+IF($L$5,25,0)+IF($L$13,20,0)+IF($L$10,25,0)+IF($J$11,16,0)+ROUNDDOWN(IF($J$12,77*(1+U6),0),0)+IF($L$8,30,0))*IF($J$10,1.1,1)*(($D$2*0.01)+1)*IF(F16,1+(0.05*$R$2),1)+IF(F19,((100*(1+(D2*0.01))*IF(J10,1.1,1))*P24*IF(F16,1+(0.05*$R$2),1)),0)+IF(F24,((50*(1+(D2*0.01))*IF(J10,1.1,1))*R3*IF(F16,1+(0.05*$R$2),1)),0),0) -> 370 | O2: Miss+Dodge% | P2: =10%+((H3-60)*1.5%)-(MIN(B8-300,15)*0.001)-MIN($N$6,((H3-60)*1%)+5%) -> 0.056 | Q2: T3.5 5pc Uptime | R2: =1 - EXP( -( (0.1 * (1 - SUM(P2:P3)) / C43) + IF(AND(J3="Windfury",C44>0),(0.1 * (1 - SUM(P2:P3)) / C44),0) ) * 12 ) -> 0.3180569 | T2: Totemic Alignment | U2: =D4*0.45 -> 0
A3: Melee AP | B3: ='Main(manual)'!B3 -> 0 | C3: Thundering Strikes | D3: ='Main(manual)'!D3 -> 5 | E3: Max Weapon Dam | F3: ='Main(manual)'!F3 -> 389 | G3: Level | H3: ='Main(manual)'!H3 -> 63 | I3: Imbue | J3: ='Main(manual)'!J3 -> Flametongue | K3: # of Tea | L3: ='Main(manual)'!L3 -> 1 | M3: Melee AP | N3: =ROUNDDOWN((100+$B$3+IF($J$15,55,0)+(($N$2*2)+IF($L$7,35,0)+IF($L$9,40,0)+(P20*130)+IF($J$8,290,0)+IF($J$9,222,0)+IF($J$15,30,0)+IF($J$3="Rockbiter",653,0)+IF(AND($J$3="Rockbiter",$F$11),653*U4,0)+IF($J$25,(120*(15/MAX(H2,15))))+IF($J$28,(260*(20/MAX(H2,20))))+IF($J$29,(200*(20/MAX(H2,20))))))*IF($J$15,1.05,1),0) -> 1462 | O3: Parry% | P3: =IF($H$3=63,14%,5%+(($H$3-60)*0.75%))*IF($H$5,0,1) -> 0 | Q3: ForgottenOrder | R3: =1-EXP(-((K67*(1-SUM(P2:P3))/C43)+IF(J3="Windfury",(K67*(1-SUM(P2:P3))/C44),0)+(K67*(1-SUM(P2:P3))/C46)+(K67*(1-SUM(P2:P3))/C49))*15) -> 0.42462563 | T3: Rockbiter | U3: 0.35
A4: Bonus Agility | B4: ='Main(manual)'!B4+100 -> 177 | C4: Totemic Alignment | D4: ='Main(manual)'!D4 -> 0 | E4: Weapon Speed | F4: ='Main(manual)'!F4 -> 3.6 | G4: No. of Targets | H4: ='Main(manual)'!H4 -> 1 | I4: Fire Totem | J4: ='Main(manual)'!J4 -> Nova+Searing | K4: # of Rune | L4: ='Main(manual)'!L4 -> 0 | M4: Agility | N4: =ROUNDDOWN(($B$4+IF(B19="Tauren",50,52)+IF(B19="Troll",5,0)+IF($J$11,16,0)+IF($L$6,25,0)+IF($L$11,25,0)+ROUNDDOWN(IF($J$13,77*(1+U6),0),0))*IF($J$10,1.1,1)*(($D$2*0.01)+1),0) -> 406 | O4: Block% | P4: =IF($H$5,0,5%) -> 0 | T4: T2.5 Rockbiter buff | U4: 0.25
A5: Phys Crit | B5: ='Main(manual)'!B5 -> 0.04 | C5: Calming Winds | D5: ='Main(manual)'!D5 -> 0 | E5: Stonebreaker Totem | F5: ='Main(manual)'!F5 -> TRUE | G5: Attacking Behind | H5: ='Main(manual)'!H5 -> TRUE | I5: Stoneclaw totem | J5: ='Main(manual)'!J5 -> FALSE | K5: Elixir of Giants | L5: ='Main(manual)'!L5 -> TRUE | M5: Phys Crit | N5: =$N$4/2000+($D$3/100)+IF($L$6,0.02,0)+IF(J14,0.03,0)+B5+0.017+(0.0004*($B$8-300)) -> 0.3652 | O5: Glancing Chance | P5: =10%+(10%*($H$3-60)) -> 0.4 | T5: Spirit Armor | U5: =0.05*D18*F20 -> 0
A6: Phys Hit | B6: ='Main(manual)'!B6 -> 0.02 | C6: Flurry | D6: ='Main(manual)'!D6 -> 5 | E6: Crackling Totem | F6: ='Main(manual)'!F6 -> TRUE | G6: Being Attacked | H6: ='Main(manual)'!H6 -> FALSE | I6: Salvation | J6: ='Main(manual)'!J6 -> TRUE | K6: Mongoose | L6: ='Main(manual)'!L6 -> TRUE | M6: Phys Hit | N6: =$B$6+($D$11/100)+(B8-300)*0.002 -> 0.076 | O6: Block Value | P6: 38 | T6: Enhancing Totems | U6: =0.125*D7 -> 0
A7: Haste | B7: ='Main(manual)'!B7 -> 0.03 | C7: Enhancing Totems | D7: ='Main(manual)'!D7 -> 0 | E7: Totem of Rage | F7: ='Main(manual)'!F7 -> TRUE | G7: Shield Proc Interval | H7: ='Main(manual)'!H7 -> 4 | I7: Tranquil Air | J7: ='Main(manual)'!J7 -> FALSE | K7: Firewater | L7: ='Main(manual)'!L7 -> TRUE | M7: Haste | N7: =(1+B7)*IF(F16,1+(0.1*R2),1)*IF($L$12,1.02,1)*IF($J$17,MIN(1+(0.2*(30/H2)),1.2),1)*(1+((IF(D6>=1,0.05,0)+($D$6*0.03))*P18))*(1+(0.08*$P$21))*IF($J$24,1+(0.1*(10/H2)),1)*IF($J$27,MIN(1+(0.2*(15/H2)),1.2),1)-1 -> 0.2165542 | O7: Glancing Damage | P7: =MIN(65%+((B8-300)*2%),95% ) -> 0.91 | T7: Calming Winds | U7: =0.0833*D5*NOT(F20) -> 0
A8: Weapon Skill | B8: ='Main(manual)'!B8 -> 313 | C8: Element's Grace | D8: ='Main(manual)'!D8 -> 4 | E8: Broken Earth totem | F8: ='Main(manual)'!F8 -> FALSE | G8: Armour | H8: ='Main(manual)'!H8 -> 4211 | I8: Battle Shout | J8: ='Main(manual)'!J8 -> TRUE | K8: Juju Power | L8: ='Main(manual)'!L8 -> FALSE | M8: Intellect | N8: =ROUNDDOWN(($B$10+IF(B19="Tauren",85,86)+IF(B19="Troll",1,0)+IF($J$18,31,0)+IF($J$11,16,0))*IF($J$10,1.1,1)*(1+($D$2*0.01)),0) -> 336 | O8: Hit% | P8: =100%-SUM(P2:P5)-MIN(P9,N5-((H3-60)*0.01)) -> 0.2088 | T8: Element's Grace | U8: =0.02*D8 -> 0.08
A9: Armor Pen | B9: ='Main(manual)'!B9 -> 500 | C9: Concussion | D9: ='Main(manual)'!D9 -> 5 | E9: Totem of Tides | F9: ='Main(manual)'!F9 -> FALSE | G9: Sunder Armour | H9: ='Main(manual)'!H9 -> TRUE | I9: Might | J9: ='Main(manual)'!J9 -> TRUE | K9: Juju Might | L9: ='Main(manual)'!L9 -> FALSE | M9: MP5 | N9: =$B$11+IF($L$15,12,0) -> 12 | O9: Crit Cap | P9: =100%-SUM(P2:P5) -> 0.544 | T9: Stormstrike | U9: =J23*0.25 -> 0.25
A10: Bonus Intellect | B10: ='Main(manual)'!B10 -> 157 | C10: Convection | D10: ='Main(manual)'!D10 -> 2 | E10: T2 3pc | F10: ='Main(manual)'!F11 -> FALSE | G10: Curse of Reck | H10: ='Main(manual)'!H10 -> TRUE | I10: Kings | J10: ='Main(manual)'!J10 -> TRUE | K10: R.O.I.D.S | L10: ='Main(manual)'!L10 -> TRUE | M10: Spirit | N10: =ROUNDDOWN(($B$12+IF($B$19="Tauren",102,101)+IF($B$19="Orc",1,0)+IF($L$14,50,0)+IF($J$19,40,0)+IF($J$11,16,0))*IF($J$10,1.1,1)*(1+($D$2*0.01)),0) -> 244 | O10: Crit% Post Suppression | P10: =N5-((H3-60)*0.01) -> 0.3352
A11: MP5 | B11: ='Main(manual)'!B11 -> 0 | C11: Ele Devastation | D11: ='Main(manual)'!D11 -> 3 | E11: T2.5 5pc | F11: ='Main(manual)'!F12 -> FALSE | G11: Faerie Fire | H11: ='Main(manual)'!H11 -> TRUE | I11: MotW | J11: ='Main(manual)'!J11 -> TRUE | K11: Scorpok Assay | L11: ='Main(manual)'!L11 -> FALSE | M11: Meditation | N11: =$B$13+IF($J$20,0.05,0) -> 0.05 | O11: Effective Armour | P11: =H8-B9-IF(H9,2250,0)-IF(H12,2550,0)+IF(AND(H9,H12),2250,0)-IF(H10,640,0)-IF(H11,505,0) -> 16
A12: Bonus Spirit | B12: ='Main(manual)'!B12 -> 5 | C12: Elemental Weapons | D12: ='Main(manual)'!D12 -> 3 | E12: T3 2pc | F12: ='Main(manual)'!F13 -> TRUE | G12: Improved EA | H12: ='Main(manual)'!H12 -> TRUE | I12: Strength of Earth | J12: ='Main(manual)'!J12 -> TRUE | K12: Tel'Abim Medley | L12: ='Main(manual)'!L12 -> FALSE | M12: Mana Per 2 (5SR) | N12: =(17+(($N$10/5)*$N$11)+($N$9/2.5))+IF($J$22,10,0)+IF($J$21,15.6,0) -> 49.84 | O12: Armour DR | P12: =P11 / (P11 + 400 + 85 * 60) -> 0.0029006526
A13: Meditation | B13: ='Main(manual)'!B13 -> 0 | C13: Reverberation | D13: ='Main(manual)'!D13 -> 3 | E13: T3 4pc | F13: ='Main(manual)'!F14 -> FALSE | G13: Hemorrhage | H13: ='Main(manual)'!H13 -> TRUE | I13: Grace of Air | J13: ='Main(manual)'!J13 -> TRUE | K13: Power Mushroom | L13: ='Main(manual)'!L13 -> FALSE | M13: Raw Mana Pool | N13: =1240+($N$8*15) -> 6280 | O13: NPC Level Resist | P13: =1-(($H$3-60)*0.02) -> 0.94
A14: Spell Pen | B14: ='Main(manual)'!B14 -> 0 | C14: Call of Flame | D14: ='Main(manual)'!D14 -> 3 | E14: T3 6pc | F14: ='Main(manual)'!F15 -> FALSE | G14: Gift of Arthas | H14: ='Main(manual)'!H14 -> FALSE | I14: Leader of Pack | J14: ='Main(manual)'!J14 -> TRUE | K14: Zanza | L14: ='Main(manual)'!L14 -> TRUE | M14: Final Mana Pool | N14: =N13+(L2*2250)+(L3*1350)+(L4*1550)+(H2/2*N12)+((N19*59/60)*H2)+IF(J2="Water",130*(H2/H7),0) -> 14178.798 | O14: Effective NR | P14: =(MAX($H$15-$B$14-IF($H$17,25,0),0)) -> 0
A15: Nature Spellpower | B15: ='Main(manual)'!B15 -> 385 | C15: Elemental Focus | D15: ='Main(manual)'!D15 -> 1 | E15: T3.5 3pc | F15: ='Main(manual)'!F16 -> FALSE | G15: NR | H15: ='Main(manual)'!H15 -> 15 | I15: Trueshot Aura | J15: ='Main(manual)'!J15 -> FALSE | K15: Mageblood | L15: ='Main(manual)'!L15 -> TRUE | M15: Nature Spellpower | N15: =B15+IF(L16,150,0)+IF(L17,35,0)+IF(L18,55,0)+IF(L20,35,0)+IF(L21,15,0)+IF(L22,22,0)+IF(F25,132*P22,0)+IF($J$25,(60*(15/MAX(H2,15)))) -> 740.13073 | O15: Effective FR | P15: =(MAX($H$16-$B$14-IF($H$18,75,0),0)) -> 0
A16: Fire Spellpower | B16: ='Main(manual)'!B16 -> 432 | C16: Improved Fire Totems | D16: ='Main(manual)'!D16 -> 2 | E16: T3.5 5pc | F16: ='Main(manual)'!F17 -> FALSE | G16: FR | H16: ='Main(manual)'!H16 -> 15 | I16: Boomy Aura | J16: ='Main(manual)'!J16 -> FALSE | K16: Supreme Power | L16: ='Main(manual)'!L16 -> TRUE | M16: Fire Spellpower | N16: =B16+IF(L16,150,0)+IF(L17,35,0)+IF(L19,40,0)+IF(L20,35,0)+IF(L21,15,0)+IF(L22,22,0)+IF(F25,132*P22,0)+IF($J$25,(60*(15/MAX(H2,15)))) -> 772.13073 | O16: Ele Dev Uptime | P16: =1 - EXP( -( (P10 * (1 - SUM(P2:P3)) / C43) + IF(J3="Windfury",(P10 * (1 - SUM(P2:P3)) / C44),0) + (MIN(1, P10 + 0.02 * D8) * (1 - SUM(P2:P3)) / C49) + (MIN(1, P10 + 0.02 * D8) * (1 - SUM(P2:P3)) / C46) ) * 10 ) -> 0.86395206
A17: Spell Crit | B17: ='Main(manual)'!B17 -> 0.07 | C17: Elemental Fury | D17: ='Main(manual)'!D17 -> 2 | E17: Threat Gloves | F17: ='Main(manual)'!F18 -> FALSE | G17: Thunderfury | H17: ='Main(manual)'!H17 -> TRUE | I17: Bloodlust | J17: ='Main(manual)'!J17 -> FALSE | K17: Arcane Elixir | L17: ='Main(manual)'!L17 -> TRUE | M17: Spell Crit | N17: =B17+(($N$8)/59.2)%+(IF(L21,2%,0))+3.53%+(IF(J16,3%,0)) -> 0.18205676 | O17: Focus Uptime | P17: =IF(D15,1-(((1-$P$10)^(5/C43))*(1-(1-SUM($P$2,$P$3))*$P$10)^2)*((1-MIN(IF($H$3=63,0.83+$N$18,0.96+$N$18-(($H$3-60)*0.01)),0.99)*($N$17+IF($F$10,0.1,0)+U8+IF($F$12,5%,0)))^2),0) -> 0.88681174
A18: Spell Hit | B18: ='Main(manual)'!B18 -> 0.03 | C18: Spirit Armor | D18: ='Main(manual)'!D18 -> 0 | E18: Subtlety Cloak | F18: ='Main(manual)'!F19 -> TRUE | G18: Curse of Elements | H18: ='Main(manual)'!H18 -> TRUE | I18: Arcane Intellect | J18: ='Main(manual)'!J18 -> TRUE | K18: Nature Power | L18: ='Main(manual)'!L18 -> TRUE | M18: Spell Hit | N18: =$P$16*MIN(B18+(D11*1%)+IF(J20,1%,0)+(D11*0.03),16%)+(1-$P$16)*MIN(B18+(D11*1%)+IF(J20,1%,0),16%) -> 0.14775569 | O18: Flurry Uptime | P18: =LET( miss, SUM($P$2,$P$3), wf_enabled, IF($J$3="Windfury", 1, 0), p_auto_base, $P$10 * (1 - miss), p_spell_base, MIN(1, $P$10 + 0.02 * $D$8) * (1 - miss), p_wf, $P$10 * (1 - miss), wf_chance, 0.2, wf_rolls, 2, p_auto_eff, p_auto_base + wf_enabled * wf_chance * (1 - (1 - p_wf)^wf_rolls) * (1 - p_auto_base), p_spell_eff, p_spell_base + wf_enabled * wf_chance * (1 - (1 - p_wf)^wf_rolls) * (1 - p_spell_base), r, p_auto_eff / MAX($C$43, 0.00001) + p_spell_eff / C49 + p_spell_eff / C46, a, 1 / MAX($C$43, 0.00001), rho, r / MAX(a, 0.00001), uptime_time, (rho * (3 + 3*rho + rho^2)) / (1 + rho)^3, uptime_time ) -> 0.75135594
A19: Race | B19: ='Main(manual)'!B19 -> Troll | C19: Imp Molten Blast | D19: ='Main(manual)'!D19 -> 1 | E19: Crusader | F19: ='Main(manual)'!F20 -> FALSE | G19: Improved Scorch | H19: ='Main(manual)'!H19 -> TRUE | I19: Divine Spirit | J19: ='Main(manual)'!J19 -> TRUE | K19: Fire Power | L19: ='Main(manual)'!L19 -> TRUE | M19: JoW Hits (60 sec) | N19: =IF($H$21,((60/C43)+14.166+IF(J3="Windfury",(60/C44),0)+IF(J3="Flametongue",((60/C43)+(60/C46)+(60/C49)),0)+$F$72)*0.5*(1-SUM($P$3,$P$2)),0) -> 47.518606 | O19: Windfury Procs (60 sec) | P19: =IF(J3="Windfury",((60/C43)+(60/C49)+(60/C46))*0.2*(1-SUM($P$3,$P$2)),0) -> 0
E20: Using Shield? | F20: ='Main(manual)'!F21 -> FALSE | G20: Nightfall | H20: ='Main(manual)'!H20 -> TRUE | I20: Emerald Blessing | J20: ='Main(manual)'!J20 -> TRUE | K20: Dreamtonic | L20: ='Main(manual)'!L20 -> TRUE | O20: Stonebreaker Uptime | P20: =IF($F$5,1-(0.65^(10/$C$51)),0) -> 0.5775
E21: Sulfuras proc | F21: ='Main(manual)'!F22 -> FALSE | G21: Judgement of Wisdom | H21: ='Main(manual)'!H21 -> TRUE | I21: Wisdom | J21: ='Main(manual)'!J21 -> TRUE | K21: Dreamshard | L21: ='Main(manual)'!L21 -> TRUE | O21: Crackling Uptime | P21: =IF($F$6,1-EXP(-(0.15/(60/(60/C46))*8)),0) -> 0.12482668
A22: TPS | B22: =$I$61 -> 1199.5185 | E22: Neretzek proc | F22: ='Main(manual)'!F23 -> FALSE | I22: Mana Spring | J22: ='Main(manual)'!J22 -> TRUE | K22: Tel'Abim Delight | L22: ='Main(manual)'!L22 -> FALSE | O22: WoC Uptime | P22: =1-EXP(-(0.05/(60/$H$72))*10) -> 0.49341459
A23: DPS | B23: =$G$61 -> 1805.6951 | E23: DTC proc | F23: ='Main(manual)'!F24 -> FALSE | I23: Stormstrike | J23: ='Main(manual)'!J23 -> TRUE | K23: D.Breath Chili | L23: ='Main(manual)'!L23 -> TRUE | O23: Nobility Drape Uptime | P23: =1-EXP(-(0.2/(60/$H$72))*6) -> 0.80449114
E24: Forgotten Order proc | F24: ='Main(manual)'!F25 -> FALSE | I24: Berserking | J24: ='Main(manual)'!J24 -> TRUE | O24: Crusader Uptime | P24: =1-EXP(-((E67*(1-SUM(P2:P3))/C43)+IF(J3="Windfury",(E67*(1-SUM(P2:P3))/C44),0)+(E67*(1-SUM(P2:P3))/C46)+(E67*(1-SUM(P2:P3))/C49))*20) -> 0.47809814
A25: Total | B25: %asPhys | C25: %asMagic | E25: Wrath of Cenarius | F25: ='Main(manual)'!F27 -> TRUE | I25: Bloodfury | J25: ='Main(manual)'!J25 -> FALSE | K25: Stat Weights | L25: Weight (dps) | M25: Weight (ap) | N25: Weight (sp)
